Workbook

Sheet Raw 24
A1: No | B1: SA | C1: ACC | D1: Date | E1: Description | F1: Paid in | G1: Paid out | H1: Balance | I1: NET | J1: Balance UC | K1: Check UC | L1: UC category
A2: 151 | B2: SA24 | C2: FY24 | D2: 45261 | E2: Automated Credit ICONIC EYEWE KUOONA LIMITED COM FP 30/11/23 1854 088430524581031101 | F2: 1200 | H2: 13590.3 | I2: =F2-G2 -> 1200 | J2: 13590.3 | K2: =H2-J2 -> 0 | L2: Income | M2: =VLOOKUP(A2,#REF!,6,FALSE) -> #REF!
A3: 152 | B3: SA24 | C3: FY24 | D3: 45261 | E3: Automated Credit BOOTS OPTICIANS PR 1003 2000004442 K | F3: 2500 | H3: 16090.3 | I3: =F3-G3 -> 2500 | J3: =J2+I3 -> 16090.3 | K3: =H3-J3 -> 0 | L3: Income | M3: =VLOOKUP(A3,#REF!,6,FALSE) -> #REF!
A4: 153 | B4: SA24 | C4: FY24 | D4: 45261 | E4: Direct Debit THE COLLEGE OF OPT DD001773 | G4: 25.42 | H4: 16064.88 | I4: =F4-G4 -> -25.42 | J4: =J3+I4 -> 16064.88 | K4: =H4-J4 -> 0 | L4: Professional - College | M4: =VLOOKUP(A4,#REF!,6,FALSE) -> #REF!
A5: 154 | B5: SA24 | C5: FY24 | D5: 45266 | E5: OnLine Transaction CHIDO HOVE In VIA MOBILE - LVP FP 05/12/23 10 01224352238059000N | G5: 1000 | H5: 15064.88 | I5: =F5-G5 -> -1000 | J5: =J4+I5 -> 15064.88 | K5: =H5-J5 -> 0 | L5: Dividend | M5: =VLOOKUP(A5,#REF!,6,FALSE) -> #REF!
A6: 155 | B6: SA24 | C6: FY24 | D6: 45267 | E6: Automated Credit VISION EXPRESS UK 200003317620 | F6: 850 | H6: 15914.88 | I6: =F6-G6 -> 850 | J6: =J5+I6 -> 15914.88 | K6: =H6-J6 -> 0 | L6: Income | M6: =VLOOKUP(A6,#REF!,6,FALSE) -> #REF!
A7: 156 | B7: SA24 | C7: FY24 | D7: 45268 | E7: Automated Credit SPECSAVERS FINANCE SPECSAVERS SEP COM | F7: 2400 | H7: 18314.88 | I7: =F7-G7 -> 2400 | J7: =J6+I7 -> 18314.88 | K7: =H7-J7 -> 0 | L7: Income | M7: =VLOOKUP(A7,#REF!,6,FALSE) -> #REF!
A8: 157 | B8: SA24 | C8: FY24 | D8: 45272 | E8: Automated Credit C HOVE CASH RETURN FP 11/12/23 2324 500000001255931510 | F8: 500 | H8: 18814.88 | I8: =F8-G8 -> 500 | J8: =J7+I8 -> 18814.88 | K8: =H8-J8 -> 0 | L8: Income | M8: =VLOOKUP(A8,#REF!,6,FALSE) -> #REF!
A9: 158 | B9: SA24 | C9: FY24 | D9: 45272 | E9: OnLine Transaction CHIDO HOVE INVEST VIA ONLINE - PYMT FP 11/12/23 10 36224100239120000N | G9: 5000 | H9: 13814.88 | I9: =F9-G9 -> -5000 | J9: =J8+I9 -> 13814.88 | K9: =H9-J9 -> 0 | L9: Dividend | M9: =VLOOKUP(A9,#REF!,6,FALSE) -> #REF!
A10: 159 | B10: SA24 | C10: FY24 | D10: 45280 | E10: Card Transaction 4163 19DEC23 C TAMAR BRIDGE PLYMOUTH GB | G10: 2.6 | H10: 13812.28 | I10: =F10-G10 -> -2.6 | J10: =J9+I10 -> 13812.28 | K10: =H10-J10 -> 0 | L10: Toll | M10: =VLOOKUP(A10,#REF!,6,FALSE) -> #REF!
A11: 160 | B11: SA24 | C11: FY24 | D11: 45653 | E11: OnLine Transaction CHIDO HOVE INVEST VIA MOBILE - PYMT FP 26/12/23 10 52121347307951000N | G11: 1000 | H11: 12812.28 | I11: =F11-G11 -> -1000 | J11: =J10+I11 -> 12812.28 | K11: =H11-J11 -> 0 | L11: Dividend | M11: =VLOOKUP(A11,#REF!,6,FALSE) -> #REF!
A12: 161 | B12: SA24 | C12: FY24 | D12: 45654 | E12: OnLine Transaction CHIDO HOVE TRANSFER VIA MOBILE - PYMT FP 28/12/23 10 30071348133982000N | G12: 1000 | H12: 11812.28 | I12: =F12-G12 -> -1000 | J12: =J11+I12 -> 11812.28 | K12: =H12-J12 -> 0 | L12: Dividend | M12: =VLOOKUP(A12,#REF!,6,FALSE) -> #REF!
A13: 162 | B13: SA24 | C13: FY24 | D13: 45293 | E13: OnLine Transaction CHIDO HOVE TRANSFER VIA MOBILE - PYMT FP 01/01/24 10 47215400526440000N | G13: 1000 | H13: 10812.28 | I13: =F13-G13 -> -1000 | J13: =J12+I13 -> 10812.28 | K13: =H13-J13 -> 0 | L13: Dividend | M13: =VLOOKUP(A13,#REF!,6,FALSE) -> #REF!
A14: 163 | B14: SA24 | C14: FY24 | D14: 45293 | E14: OnLine Transaction CHIDO HOVE TRANSFER VIA MOBILE - PYMT FP 30/12/23 10 59132623308479000N | G14: 1000 | H14: 9812.28 | I14: =F14-G14 -> -1000 | J14: =J13+I14 -> 9812.28 | K14: =H14-J14 -> 0 | L14: Dividend | M14: =VLOOKUP(A14,#REF!,6,FALSE) -> #REF!
A15: 164 | B15: SA24 | C15: FY24 | D15: 45293 | E15: Card Transaction 4163 30DEC23 C TESCO-STORES-6106 CALLINGTON GB | G15: 30.7 | H15: 9781.58 | I15: =F15-G15 -> -30.7 | J15: =J14+I15 -> 9781.58 | K15: =H15-J15 -> 0 | L15: Trivial | M15: =VLOOKUP(A15,#REF!,6,FALSE) -> #REF!
A16: 165 | B16: SA24 | C16: FY24 | D16: 45293 | E16: Direct Debit THE COLLEGE OF OPT DD001773 | G16: 25.42 | H16: 9756.16 | I16: =F16-G16 -> -25.42 | J16: =J15+I16 -> 9756.16 | K16: =H16-J16 -> 0 | L16: Professional - College | M16: =VLOOKUP(A16,#REF!,6,FALSE) -> #REF!
A17: 166 | B17: SA24 | C17: FY24 | D17: 45293 | E17: Direct Debit ASSOC OPTOMETRISTS 0000070593 | G17: 72 | H17: 9684.16 | I17: =F17-G17 -> -72 | J17: =J16+I17 -> 9684.16 | K17: =H17-J17 -> 0 | L17: Professional - AOP | M17: =VLOOKUP(A17,#REF!,6,FALSE) -> #REF!
A18: 167 | B18: SA24 | C18: FY24 | D18: 45296 | E18: Automated Credit SPECSAVERS FINANCE SPECSAVERS SEP COM | F18: 1600 | H18: 11284.16 | I18: =F18-G18 -> 1600 | J18: =J17+I18 -> 11284.16 | K18: =H18-J18 -> 0 | L18: Income | M18: =VLOOKUP(A18,#REF!,6,FALSE) -> #REF!
A19: 168 | B19: SA24 | C19: FY24 | D19: 45301 | E19: Automated Credit SPECSAVERS FINANCE SPECSAVERS SEP COM | F19: 2500 | H19: 13784.16 | I19: =F19-G19 -> 2500 | J19: =J18+I19 -> 13784.16 | K19: =H19-J19 -> 0 | L19: Income | M19: =VLOOKUP(A19,#REF!,6,FALSE) -> #REF!
A20: 169 | B20: SA24 | C20: FY24 | D20: 45301 | E20: Card Transaction 4163 09JAN24 C TAMAR BRIDGE PLYMOUTH GB | G20: 2.6 | H20: 13781.56 | I20: =F20-G20 -> -2.6 | J20: =J19+I20 -> 13781.56 | K20: =H20-J20 -> 0 | L20: Toll | M20: =VLOOKUP(A20,#REF!,6,FALSE) -> #REF!
A21: 170 | B21: SA24 | C21: FY24 | D21: 45303 | E21: Automated Credit LOCUM MATCH LIMITE ASDA PAYMENT FP 12/01/24 0232 05023128353259000J ASDA PAYMENT | F21: 1760 | H21: 15541.56 | I21: =F21-G21 -> 1760 | J21: =J20+I21 -> 15541.56 | K21: =H21-J21 -> 0 | L21: Income | M21: =VLOOKUP(A21,#REF!,6,FALSE) -> #REF!
A22: 171 | B22: SA24 | C22: FY24 | D22: 45303 | E22: Card Transaction 4163 11JAN24 C TAMAR BRIDGE PLYMOUTH GB | G22: 2.6 | H22: 15538.96 | I22: =F22-G22 -> -2.6 | J22: =J21+I22 -> 15538.96 | K22: =H22-J22 -> 0 | L22: Toll | M22: =VLOOKUP(A22,#REF!,6,FALSE) -> #REF!
A23: 172 | B23: SA24 | C23: FY24 | D23: 45306 | E23: OnLine Transaction CHIDO HOVE TRANSFER VIA MOBILE - | G23: 1000 | H23: 14538.96 | I23: =F23-G23 -> -1000 | J23: =J22+I23 -> 14538.96 | K23: =H23-J23 -> 0 | L23: Dividend | M23: =VLOOKUP(A23,#REF!,6,FALSE) -> #REF!
A24: 173 | B24: SA24 | C24: FY24 | D24: 45306 | E24: Card Transaction 4163 13JAN24 C TESCO-STORES-6106 | G24: 22.02 | H24: 14516.94 | I24: =F24-G24 -> -22.02 | J24: =J23+I24 -> 14516.94 | K24: =H24-J24 -> 0 | L24: Trivial | M24: =VLOOKUP(A24,#REF!,6,FALSE) -> #REF!
A25: 174 | B25: SA24 | C25: FY24 | D25: 45310 | E25: Automated Credit LOCUM MATCH LIMITE ASDA PAYMENT | F25: 440 | H25: 14956.94 | I25: =F25-G25 -> 440 | J25: =J24+I25 -> 14956.94 | K25: =H25-J25 -> 0 | L25: Income | M25: =VLOOKUP(A25,#REF!,6,FALSE) -> #REF!
A26: 175 | B26: SA24 | C26: FY24 | D26: 45310 | E26: Automated Credit SPECSAVERS FINANCE SPECSAVERS SEP | F26: 1500 | H26: 16456.94 | I26: =F26-G26 -> 1500 | J26: =J25+I26 -> 16456.94 | K26: =H26-J26 -> 0 | L26: Income | M26: =VLOOKUP(A26,#REF!,6,FALSE) -> #REF!
A27: 176 | B27: SA24 | C27: FY24 | D27: 45314 | E27: Card Transaction 4163 22JAN24 C TAMAR BRIDGE PLYMOUTH GB | G27: 2.6 | H27: 16454.34 | I27: =F27-G27 -> -2.6 | J27: =J26+I27 -> 16454.34 | K27: =H27-J27 -> 0 | L27: Toll | M27: =VLOOKUP(A27,#REF!,6,FALSE) -> #REF!
A28: 177 | B28: SA24 | C28: FY24 | D28: 45315 | E28: Card Transaction 4163 22JAN24 HTTPS://WWW .PLYMOUTH.G 01752668000 GB | G28: 2.8 | H28: 16451.54 | I28: =F28-G28 -> -2.8 | J28: =J27+I28 -> 16451.54 | K28: =H28-J28 -> 0 | L28: Parking | M28: =VLOOKUP(A28,#REF!,6,FALSE) -> #REF!
A29: 178 | B29: SA24 | C29: FY24 | D29: 45315 | E29: Automated Credit SPECSAVERS FINANCE SPECSAVERS SEP COM | F29: 399.97 | H29: 16851.51 | I29: =F29-G29 -> 399.97 | J29: =J28+I29 -> 16851.51 | K29: =H29-J29 -> 0 | L29: Income | M29: =VLOOKUP(A29,#REF!,6,FALSE) -> #REF!
A30: 179 | B30: SA24 | C30: FY24 | D30: 45316 | E30: Card Transaction 4163 23JAN24 C TAMAR BRIDGE PLYMOUTH GB | G30: 2.6 | H30: 16848.91 | I30: =F30-G30 -> -2.6 | J30: =J29+I30 -> 16848.91 | K30: =H30-J30 -> 0 | L30: Toll | M30: =VLOOKUP(A30,#REF!,6,FALSE) -> #REF!
A31: 180 | B31: SA24 | C31: FY24 | D31: 45316 | E31: Card Transaction 4163 23JAN24 C TAMAR BRIDGE PLYMOUTH GB | G31: 2.6 | H31: 16846.31 | I31: =F31-G31 -> -2.6 | J31: =J30+I31 -> 16846.31 | K31: =H31-J31 -> 0 | L31: Toll | M31: =VLOOKUP(A31,#REF!,6,FALSE) -> #REF!
A32: 181 | B32: SA24 | C32: FY24 | D32: 45320 | E32: Automated Credit ICONIC EYEWE KUOONA LIMITED COM FP 27/01/24 1359 507114009531721001 | F32: 400 | H32: 17246.31 | I32: =F32-G32 -> 400 | J32: =J31+I32 -> 17246.31 | K32: =H32-J32 -> 0 | L32: Income | M32: =VLOOKUP(A32,#REF!,6,FALSE) -> #REF!
A33: 182 | B33: SA24 | C33: FY24 | D33: 45320 | E33: OnLine Transaction CHIDO HOVE TRANSFER VIA MOBILE - PYMT FP 29/01/24 10 41083427398667000N | G33: 1000 | H33: 16246.31 | I33: =F33-G33 -> -1000 | J33: =J32+I33 -> 16246.31 | K33: =H33-J33 -> 0 | L33: Dividend | M33: =VLOOKUP(A33,#REF!,6,FALSE) -> #REF!
A34: 183 | B34: SA24 | C34: FY24 | D34: 45322 | E34: Automated Credit SPECSAVERS FINANCE SPECSAVERS SEP COM | F34: 2000 | H34: 18246.31 | I34: =F34-G34 -> 2000 | J34: =J33+I34 -> 18246.31 | K34: =H34-J34 -> 0 | L34: Income | M34: =VLOOKUP(A34,#REF!,6,FALSE) -> #REF!
A35: 184 | B35: SA24 | C35: FY24 | D35: 45323 | E35: Direct Debit THE COLLEGE OF OPT DD00177 | G35: 25.42 | H35: 18220.89 | I35: =F35-G35 -> -25.42 | J35: =J34+I35 -> 18220.89 | K35: =H35-J35 -> 0 | L35: Professional - College | M35: =VLOOKUP(A35,#REF!,6,FALSE) -> #REF!
A36: 185 | B36: SA24 | C36: FY24 | D36: 45323 | E36: Direct Debit ASSOC OPTOMETRISTS 0000070593 | G36: 72 | H36: 18148.89 | I36: =F36-G36 -> -72 | J36: =J35+I36 -> 18148.89 | K36: =H36-J36 -> 0 | L36: Professional - AOP | M36: =VLOOKUP(A36,#REF!,6,FALSE) -> #REF!
A37: 186 | B37: SA24 | C37: FY24 | D37: 45324 | E37: Automated Credit LOCUM PAYROL LTD ASDA FP 02/02/24 0427 MF06680E05C8E5B000 | F37: 880 | H37: 19028.89 | I37: =F37-G37 -> 880 | J37: =J36+I37 -> 19028.89 | K37: =H37-J37 -> 0 | L37: Income | M37: =VLOOKUP(A37,#REF!,6,FALSE) -> #REF!
A38: 187 | B38: SA24 | C38: FY24 | D38: 45324 | E38: OnLine Transaction CHIDO HOVE TRANSFER VIA ONLINE - PYMT FP 01/02/24 10 60200431240120000N | G38: 3000 | H38: 16028.89 | I38: =F38-G38 -> -3000 | J38: =J37+I38 -> 16028.89 | K38: =H38-J38 -> 0 | L38: Dividend | M38: =VLOOKUP(A38,#REF!,6,FALSE) -> #REF!
A39: 188 | B39: SA24 | C39: FY24 | D39: 45324 | E39: Card Transaction 4163 01FEB24 C TAMAR BRIDGE PLYMOUTH GB | G39: 2.6 | H39: 16026.29 | I39: =F39-G39 -> -2.6 | J39: =J38+I39 -> 16026.29 | K39: =H39-J39 -> 0 | L39: Toll | M39: =VLOOKUP(A39,#REF!,6,FALSE) -> #REF!
A40: 189 | B40: SA24 | C40: FY24 | D40: 45330 | E40: Card Transaction 4163 01FEB24 C TAMAR BRIDGE PLYMOUTH GB | G40: 2.6 | H40: 16023.69 | I40: =F40-G40 -> -2.6 | J40: =J39+I40 -> 16023.69 | K40: =H40-J40 -> 0 | L40: Toll | M40: =VLOOKUP(A40,#REF!,6,FALSE) -> #REF!
...

Sheet Analysis 24
A3: Sum of NET | B3: Column Labels
A4: Row Labels | B4: FY24 | C4: FY25
A5: AOP | B5: =SUMIFS('Raw 24'!$I:$I,'Raw 24'!$C:$C,$B$4,'Raw 24'!$L:$L,$A5) -> 0 | C5: =SUMIFS('Raw 24'!$I:$I,'Raw 24'!$C:$C,$C$4,'Raw 24'!$L:$L,$A5) -> -86.16
A6: Accountancy | B6: =SUMIFS('Raw 24'!$I:$I,'Raw 24'!$C:$C,$B$4,'Raw 24'!$L:$L,$A6) -> -613 | C6: =SUMIFS('Raw 24'!$I:$I,'Raw 24'!$C:$C,$C$4,'Raw 24'!$L:$L,$A6) -> 0
A7: Bank charges | B7: =SUMIFS('Raw 24'!$I:$I,'Raw 24'!$C:$C,$B$4,'Raw 24'!$L:$L,$A7) -> -32.9 | C7: =SUMIFS('Raw 24'!$I:$I,'Raw 24'!$C:$C,$C$4,'Raw 24'!$L:$L,$A7) -> -9.1
A8: DLA | B8: =SUMIFS('Raw 24'!$I:$I,'Raw 24'!$C:$C,$B$4,'Raw 24'!$L:$L,$A8) -> -76.28 | C8: =SUMIFS('Raw 24'!$I:$I,'Raw 24'!$C:$C,$C$4,'Raw 24'!$L:$L,$A8) -> 0
A9: Dinner | B9: =SUMIFS('Raw 24'!$I:$I,'Raw 24'!$C:$C,$B$4,'Raw 24'!$L:$L,$A9) -> -54.45 | C9: =SUMIFS('Raw 24'!$I:$I,'Raw 24'!$C:$C,$C$4,'Raw 24'!$L:$L,$A9) -> 0
A10: Dividend | B10: =SUMIFS('Raw 24'!$I:$I,'Raw 24'!$C:$C,$B$4,'Raw 24'!$L:$L,$A10) -> -60053.41 | C10: =SUMIFS('Raw 24'!$I:$I,'Raw 24'!$C:$C,$C$4,'Raw 24'!$L:$L,$A10) -> -5000
A11: Entertainment | B11: =SUMIFS('Raw 24'!$I:$I,'Raw 24'!$C:$C,$B$4,'Raw 24'!$L:$L,$A11) -> 0 | C11: =SUMIFS('Raw 24'!$I:$I,'Raw 24'!$C:$C,$C$4,'Raw 24'!$L:$L,$A11) -> -7.5
A12: Equipment | B12: =SUMIFS('Raw 24'!$I:$I,'Raw 24'!$C:$C,$B$4,'Raw 24'!$L:$L,$A12) -> -195.28 | C12: =SUMIFS('Raw 24'!$I:$I,'Raw 24'!$C:$C,$C$4,'Raw 24'!$L:$L,$A12) -> 0
A13: HMRC | B13: =SUMIFS('Raw 24'!$I:$I,'Raw 24'!$C:$C,$B$4,'Raw 24'!$L:$L,$A13) -> 7671.08 | C13: =SUMIFS('Raw 24'!$I:$I,'Raw 24'!$C:$C,$C$4,'Raw 24'!$L:$L,$A13) -> 0
A14: HMRC CT | B14: =SUMIFS('Raw 24'!$I:$I,'Raw 24'!$C:$C,$B$4,'Raw 24'!$L:$L,$A14) -> 0 | C14: =SUMIFS('Raw 24'!$I:$I,'Raw 24'!$C:$C,$C$4,'Raw 24'!$L:$L,$A14) -> -15587.61
A15: HMRC SA | B15: =SUMIFS('Raw 24'!$I:$I,'Raw 24'!$C:$C,$B$4,'Raw 24'!$L:$L,$A15) -> -4506.33 | C15: =SUMIFS('Raw 24'!$I:$I,'Raw 24'!$C:$C,$C$4,'Raw 24'!$L:$L,$A15) -> 0
A16: HMRC-CT | B16: =SUMIFS('Raw 24'!$I:$I,'Raw 24'!$C:$C,$B$4,'Raw 24'!$L:$L,$A16) -> -8287.99 | C16: =SUMIFS('Raw 24'!$I:$I,'Raw 24'!$C:$C,$C$4,'Raw 24'!$L:$L,$A16) -> 0
... A33: Trivial | B33: =SUMIFS('Raw 24'!$I:$I,'Raw 24'!$C:$C,$B$4,'Raw 24'!$L:$L,$A33) -> -52.72 | C33: =SUMIFS('Raw 24'!$I:$I,'Raw 24'!$C:$C,$C$4,'Raw 24'!$L:$L,$A33) -> 0
A34: Grand Total | B34: =SUM(B5:B33) -> 15095.7 | C34: =SUM(C5:C33) -> -25509.53
