Workbook

Sheet RAW 2025
A1: No | B1: SA | C1: FY | D1: Date | E1: Counter Party | F1: Reference | G1: Type | H1: Amount (GBP) | I1: IN | J1: OUT | K1: Balance (GBP) | L1: Net | M1: Balance UC | N1: Check | O1: Spending Category | P1: UC Category
K2: 13312.51
A3: 1 | B3: SA24/25 | C3: FY25 | D3: 45384 | E3: Barclays Current | F3: 208813 93228126 | G3: FASTER PAYMENT | H3: -700 | J3: =IF(H3<0,H3,"") -> -700 | K3: 12612.51 | L3: =I3+J3 -> -700 | M3: =K2+L3 -> 12612.51 | N3: =K3-M3 -> 0 | O3: DIRECTORS_WAGES | P3: Directors salary
A4: 2 | B4: SA24/25 | C4: FY25 | D4: 45384 | E4: M Carlin | F4: ACCOUNTS | G4: FASTER PAYMENT | H4: -40 | J4: =IF(H4<0,H4,"") -> -40 | K4: 12572.51 | L4: =I4+J4 -> -40 | M4: =K3+L4 -> 12572.51 | N4: =K4-M4 -> 0 | O4: OTHER | P4: Accountancy fee
A5: 3 | B5: SA24/25 | C5: FY25 | D5: 45385 | E5: Association Of Optometrists | F5: 87201 | G5: DIRECT DEBIT | H5: -72 | J5: =IF(H5<0,H5,"") -> -72 | K5: 12500.51 | L5: =I5+J5 -> -72 | M5: =K4+L5 -> 12500.51 | N5: =K5-M5 -> 0 | O5: PROFESSIONAL_SERVICES | P5: AOP
A6: 4 | B6: SA24/25 | C6: FY25 | D6: 45386 | E6: Lser Connect Ecom | F6: LSER CONNECT ECOM | G6: APPLE PAY | H6: -6.9 | J6: =IF(H6<0,H6,"") -> -6.9 | K6: 12493.61 | L6: =I6+J6 -> -6.9 | M6: =K5+L6 -> 12493.61 | N6: =K6-M6 -> 0 | O6: TRAVEL | P6: Travel
A7: 5 | B7: SA24/25 | C7: FY25 | D7: 45387 | E7: Specsavers | F7: SPECSAVERS SEP COM | G7: DIRECT CREDIT | H7: 850 | I7: =IF(H7>0,H7,"") -> 850 | K7: 13343.61 | L7: =I7+J7 -> 850 | M7: =K6+L7 -> 13343.61 | N7: =K7-M7 -> 0 | O7: REVENUE | P7: Income
A8: 6 | B8: SA24/25 | C8: FY25 | D8: 45390 | E8: Barclays Current | F8: Dividend | G8: FASTER PAYMENT | H8: -3500 | J8: =IF(H8<0,H8,"") -> -3500 | K8: 9843.61 | L8: =I8+J8 -> -3500 | M8: =K7+L8 -> 9843.61 | N8: =K8-M8 -> 0 | O8: DIVIDENDS | P8: Dividends
A9: 7 | B9: SA24/25 | C9: FY25 | D9: 45392 | E9: Specsavers | F9: SPECSAVERS SEP COM | G9: DIRECT CREDIT | H9: 2825 | I9: =IF(H9>0,H9,"") -> 2825 | K9: 12668.61 | L9: =I9+J9 -> 2825 | M9: =K8+L9 -> 12668.61 | N9: =K9-M9 -> 0 | O9: REVENUE | P9: Income
A10: 8 | B10: SA24/25 | C10: FY25 | D10: 45394 | E10: Finch House Cafe | F10: Finch House Cafe | G10: APPLE PAY | H10: -11.15 | J10: =IF(H10<0,H10,"") -> -11.15 | K10: 12657.46 | L10: =I10+J10 -> -11.15 | M10: =K9+L10 -> 12657.46 | N10: =K10-M10 -> 0 | O10: FOOD_AND_DRINK | P10: Lunch
A11: 9 | B11: SA24/25 | C11: FY25 | D11: 45399 | E11: Specsavers | F11: SPECSAVERS SEP COM | G11: DIRECT CREDIT | H11: 2550 | I11: =IF(H11>0,H11,"") -> 2550 | K11: 15207.46 | L11: =I11+J11 -> 2550 | M11: =K10+L11 -> 15207.46 | N11: =K11-M11 -> 0 | O11: REVENUE | P11: Income
A12: 10 | B12: SA24/25 | C12: FY25 | D12: 45406 | E12: Specsavers | F12: SPECSAVERS SEP COM | G12: DIRECT CREDIT | H12: 425 | I12: =IF(H12>0,H12,"") -> 425 | K12: 15632.46 | L12: =I12+J12 -> 425 | M12: =K11+L12 -> 15632.46 | N12: =K12-M12 -> 0 | O12: REVENUE | P12: Income
A13: 11 | B13: SA24/25 | C13: FY25 | D13: 45407 | E13: Redwood | F13: REDWOOD | G13: APPLE PAY | H13: -13.8 | J13: =IF(H13<0,H13,"") -> -13.8 | K13: 15618.66 | L13: =I13+J13 -> -13.8 | M13: =K12+L13 -> 15618.66 | N13: =K13-M13 -> 0 | O13: FOOD_AND_DRINK | P13: Lunch
A14: 12 | B14: SA24/25 | C14: FY25 | D14: 45407 | E14: Redwood | F14: REDWOOD | G14: APPLE PAY | H14: -6.9 | J14: =IF(H14<0,H14,"") -> -6.9 | K14: 15611.76 | L14: =I14+J14 -> -6.9 | M14: =K13+L14 -> 15611.76 | N14: =K14-M14 -> 0 | O14: FOOD_AND_DRINK | P14: Lunch
A15: 13 | B15: SA24/25 | C15: FY25 | D15: 45407 | E15: TfL | F15: TFL TRAVEL CH | G15: APPLE PAY | H15: -8.4 | J15: =IF(H15<0,H15,"") -> -8.4 | K15: 15603.36 | L15: =I15+J15 -> -8.4 | M15: =K14+L15 -> 15603.36 | N15: =K15-M15 -> 0 | O15: TRAVEL | P15: Travel
A16: 14 | B16: SA24/25 | C16: FY25 | D16: 45408 | E16: Bexley Ringo Ecom | F16: BEXLEY RINGO ECOM | G16: APPLE PAY | H16: -1.7 | J16: =IF(H16<0,H16,"") -> -1.7 | K16: 15601.66 | L16: =I16+J16 -> -1.7 | M16: =K15+L16 -> 15601.66 | N16: =K16-M16 -> 0 | O16: TRAVEL | P16: Travel
A17: 15 | B17: SA24/25 | C17: FY25 | D17: 45409 | E17: LOOKING GOOD OPTICIANS LIMITED T AS | F17: wadhurst | G17: FASTER PAYMENT | H17: 700 | I17: =IF(H17>0,H17,"") -> 700 | K17: 16301.66 | L17: =I17+J17 -> 700 | M17: =K16+L17 -> 16301.66 | N17: =K17-M17 -> 0 | O17: REVENUE | P17: Income
A18: 16 | B18: SA24/25 | C18: FY25 | D18: 45413 | E18: Association Of Optometrists | F18: 87201 | G18: DIRECT DEBIT | H18: -72 | J18: =IF(H18<0,H18,"") -> -72 | K18: 16229.66 | L18: =I18+J18 -> -72 | M18: =K17+L18 -> 16229.66 | N18: =K18-M18 -> 0 | O18: PROFESSIONAL_SERVICES | P18: AOP
A19: 17 | B19: SA24/25 | C19: FY25 | D19: 45413 | E19: Barclays Current | F19: 208813 93228126 | G19: FASTER PAYMENT | H19: -700 | J19: =IF(H19<0,H19,"") -> -700 | K19: 15529.66 | L19: =I19+J19 -> -700 | M19: =K18+L19 -> 15529.66 | N19: =K19-M19 -> 0 | O19: DIRECTORS_WAGES | P19: Directors salary
A20: 18 | B20: SA24/25 | C20: FY25 | D20: 45413 | E20: M Carlin | F20: ACCOUNTS | G20: FASTER PAYMENT | H20: -40 | J20: =IF(H20<0,H20,"") -> -40 | K20: 15489.66 | L20: =I20+J20 -> -40 | M20: =K19+L20 -> 15489.66 | N20: =K20-M20 -> 0 | O20: PROFESSIONAL_SERVICES | P20: Accountancy fee
A21: 19 | B21: SA24/25 | C21: FY25 | D21: 45419 | E21: Barclays Current | F21: Dividend | G21: FASTER PAYMENT | H21: -4000 | J21: =IF(H21<0,H21,"") -> -4000 | K21: 11489.66 | L21: =I21+J21 -> -4000 | M21: =K20+L21 -> 11489.66 | N21: =K21-M21 -> 0 | O21: DIVIDENDS | P21: Dividends
A22: 20 | B22: SA24/25 | C22: FY25 | D22: 45422 | E22: Specsavers | F22: SPECSAVERS SEP COM | G22: DIRECT CREDIT | H22: 1225 | I22: =IF(H22>0,H22,"") -> 1225 | K22: 12714.66 | L22: =I22+J22 -> 1225 | M22: =K21+L22 -> 12714.66 | N22: =K22-M22 -> 0 | O22: REVENUE | P22: Income
A23: 21 | B23: SA24/25 | C23: FY25 | D23: 45426 | E23: RingGo | F23: RINGGO PARKING | G23: APPLE PAY | H23: -7 | J23: =IF(H23<0,H23,"") -> -7 | K23: 12707.66 | L23: =I23+J23 -> -7 | M23: =K22+L23 -> 12707.66 | N23: =K23-M23 -> 0 | O23: TRAVEL | P23: Travel
A24: 22 | B24: SA24/25 | C24: FY25 | D24: 45427 | E24: Specsavers | F24: SPECSAVERS SEP COM | G24: DIRECT CREDIT | H24: 5450 | I24: =IF(H24>0,H24,"") -> 5450 | K24: 18157.66 | L24: =I24+J24 -> 5450 | M24: =K23+L24 -> 18157.66 | N24: =K24-M24 -> 0 | O24: REVENUE | P24: Income
A25: 23 | B25: SA24/25 | C25: FY25 | D25: 45434 | E25: Specsavers | F25: SPECSAVERS SEP COM | G25: DIRECT CREDIT | H25: 500 | I25: =IF(H25>0,H25,"") -> 500 | K25: 18657.66 | L25: =I25+J25 -> 500 | M25: =K24+L25 -> 18657.66 | N25: =K25-M25 -> 0 | O25: REVENUE | P25: Income
A26: 24 | B26: SA24/25 | C26: FY25 | D26: 45435 | E26: Tmchartered Limited | F26: Accounts | G26: FASTER PAYMENT | H26: -300 | J26: =IF(H26<0,H26,"") -> -300 | K26: 18357.66 | L26: =I26+J26 -> -300 | M26: =K25+L26 -> 18357.66 | N26: =K26-M26 -> 0 | O26: PROFESSIONAL_SERVICES | P26: Accountancy fee
A27: 25 | B27: SA24/25 | C27: FY25 | D27: 45439 | E27: RingGo | F27: RINGGO PARKING | G27: APPLE PAY | H27: -2.1 | J27: =IF(H27<0,H27,"") -> -2.1 | K27: 18355.56 | L27: =I27+J27 -> -2.1 | M27: =K26+L27 -> 18355.56 | N27: =K27-M27 -> 0 | O27: TRAVEL | P27: Travel
A28: 26 | B28: SA24/25 | C28: FY25 | D28: 45441 | E28: LOOKING GOOD OPTICIANS LIMITED T AS | F28: wadhurst | G28: FASTER PAYMENT | H28: 200 | I28: =IF(H28>0,H28,"") -> 200 | K28: 18555.56 | L28: =I28+J28 -> 200 | M28: =K27+L28 -> 18555.56 | N28: =K28-M28 -> 0 | O28: REVENUE | P28: Income
A29: 27 | B29: SA24/25 | C29: FY25 | D29: 45443 | E29: MiPermit | F29: MIPERMIT LTD | G29: APPLE PAY | H29: -1.1 | J29: =IF(H29<0,H29,"") -> -1.1 | K29: 18554.46 | L29: =I29+J29 -> -1.1 | M29: =K28+L29 -> 18554.46 | N29: =K29-M29 -> 0 | O29: TRAVEL | P29: Travel
A30: 28 | B30: SA24/25 | C30: FY25 | D30: 45443 | E30: MiPermit | F30: MIPERMIT LTD | G30: APPLE PAY | H30: -1 | J30: =IF(H30<0,H30,"") -> -1 | K30: 18553.46 | L30: =I30+J30 -> -1 | M30: =K29+L30 -> 18553.46 | N30: =K30-M30 -> 0 | O30: TRAVEL | P30: Travel
A31: 29 | B31: SA24/25 | C31: FY25 | D31: 45446 | E31: Barclays Current | F31: 208813 93228126 | G31: FASTER PAYMENT | H31: -700 | J31: =IF(H31<0,H31,"") -> -700 | K31: 17853.46 | L31: =I31+J31 -> -700 | M31: =K30+L31 -> 17853.46 | N31: =K31-M31 -> 0 | O31: DIRECTORS_WAGES | P31: Directors salary
A32: 30 | B32: SA24/25 | C32: FY25 | D32: 45446 | E32: Association Of Optometrists | F32: 87201 | G32: DIRECT DEBIT | H32: -72 | J32: =IF(H32<0,H32,"") -> -72 | K32: 17781.46 | L32: =I32+J32 -> -72 | M32: =K31+L32 -> 17781.46 | N32: =K32-M32 -> 0 | O32: PROFESSIONAL_SERVICES | P32: AOP
A33: 31 | B33: SA24/25 | C33: FY25 | D33: 45446 | E33: The College Of Optometrists | F33: DD003133 | G33: DIRECT DEBIT | H33: -127.09 | J33: =IF(H33<0,H33,"") -> -127.09 | K33: 17654.37 | L33: =I33+J33 -> -127.09 | M33: =K32+L33 -> 17654.37 | N33: =K33-M33 -> 0 | O33: PROFESSIONAL_SERVICES | P33: College
A34: 32 | B34: SA24/25 | C34: FY25 | D34: 45450 | E34: Specsavers | F34: SPECSAVERS SEP COM | G34: DIRECT CREDIT | H34: 3400 | I34: =IF(H34>0,H34,"") -> 3400 | K34: 21054.37 | L34: =I34+J34 -> 3400 | M34: =K33+L34 -> 21054.37 | N34: =K34-M34 -> 0 | O34: REVENUE | P34: Income
A35: 33 | B35: SA24/25 | C35: FY25 | D35: 45451 | E35: MiPermit | F35: MIPERMIT LTD | G35: APPLE PAY | H35: -1.1 | J35: =IF(H35<0,H35,"") -> -1.1 | K35: 21053.27 | L35: =I35+J35 -> -1.1 | M35: =K34+L35 -> 21053.27 | N35: =K35-M35 -> 0 | O35: TRAVEL | P35: Travel
A36: 34 | B36: SA24/25 | C36: FY25 | D36: 45451 | E36: MiPermit | F36: MIPERMIT LTD | G36: APPLE PAY | H36: -1 | J36: =IF(H36<0,H36,"") -> -1 | K36: 21052.27 | L36: =I36+J36 -> -1 | M36: =K35+L36 -> 21052.27 | N36: =K36-M36 -> 0 | O36: TRAVEL | P36: Travel
A37: 35 | B37: SA24/25 | C37: FY25 | D37: 45451 | E37: MiPermit | F37: MIPERMIT LTD | G37: APPLE PAY | H37: -1.1 | J37: =IF(H37<0,H37,"") -> -1.1 | K37: 21051.17 | L37: =I37+J37 -> -1.1 | M37: =K36+L37 -> 21051.17 | N37: =K37-M37 -> 0 | O37: TRAVEL | P37: Travel
A38: 36 | B38: SA24/25 | C38: FY25 | D38: 45451 | E38: MiPermit | F38: MIPERMIT LTD | G38: APPLE PAY | H38: -1.1 | J38: =IF(H38<0,H38,"") -> -1.1 | K38: 21050.07 | L38: =I38+J38 -> -1.1 | M38: =K37+L38 -> 21050.07 | N38: =K38-M38 -> 0 | O38: TRAVEL | P38: Travel
A39: 37 | B39: SA24/25 | C39: FY25 | D39: 45455 | E39: Specsavers | F39: SPECSAVERS SEP COM | G39: DIRECT CREDIT | H39: 3300 | I39: =IF(H39>0,H39,"") -> 3300 | K39: 24350.07 | L39: =I39+J39 -> 3300 | M39: =K38+L39 -> 24350.07 | N39: =K39-M39 -> 0 | O39: REVENUE | P39: Income
A40: 38 | B40: SA24/25 | C40: FY25 | D40: 45461 | E40: Tmchartered Limited | F40: Accounts MF | G40: FASTER PAYMENT | H40: -300 | J40: =IF(H40<0,H40,"") -> -300 | K40: 24050.07 | L40: =I40+J40 -> -300 | M40: =K39+L40 -> 24050.07 | N40: =K40-M40 -> 0 | O40: PROFESSIONAL_SERVICES | P40: Accountancy fee
...

Sheet Analysis
A3: Sum of NET | B3: Column Labels
A4: Row Labels | B4: FY24 | C4: FY25
A5: AOP | B5: =SUMIFS('RAW 2025'!$L:$L,'RAW 2025'!$C:$C,$B$4,'RAW 2025'!$P:$P,$A5) -> -73 | C5: =SUMIFS('RAW 2025'!$L:$L,'RAW 2025'!$C:$C,$C$4,'RAW 2025'!$P:$P,$A5) -> -1383
A6: Accountancy | B6: =SUMIFS('RAW 2025'!$L:$L,'RAW 2025'!$C:$C,$B$4,'RAW 2025'!$P:$P,$A6) -> 0 | C6: =SUMIFS('RAW 2025'!$L:$L,'RAW 2025'!$C:$C,$C$4,'RAW 2025'!$P:$P,$A6) -> -634
A7: Accountancy fee | B7: =SUMIFS('RAW 2025'!$L:$L,'RAW 2025'!$C:$C,$B$4,'RAW 2025'!$P:$P,$A7) -> 0 | C7: =SUMIFS('RAW 2025'!$L:$L,'RAW 2025'!$C:$C,$C$4,'RAW 2025'!$P:$P,$A7) -> -1016
A8: Car insurance | B8: =SUMIFS('RAW 2025'!$L:$L,'RAW 2025'!$C:$C,$B$4,'RAW 2025'!$P:$P,$A8) -> 0 | C8: =SUMIFS('RAW 2025'!$L:$L,'RAW 2025'!$C:$C,$C$4,'RAW 2025'!$P:$P,$A8) -> 193.25
A9: College | B9: =SUMIFS('RAW 2025'!$L:$L,'RAW 2025'!$C:$C,$B$4,'RAW 2025'!$P:$P,$A9) -> 0 | C9: =SUMIFS('RAW 2025'!$L:$L,'RAW 2025'!$C:$C,$C$4,'RAW 2025'!$P:$P,$A9) -> -443.09
A10: DBS | B10: =SUMIFS('RAW 2025'!$L:$L,'RAW 2025'!$C:$C,$B$4,'RAW 2025'!$P:$P,$A10) -> 0 | C10: =SUMIFS('RAW 2025'!$L:$L,'RAW 2025'!$C:$C,$C$4,'RAW 2025'!$P:$P,$A10) -> -16
A11: DLA | B11: =SUMIFS('RAW 2025'!$L:$L,'RAW 2025'!$C:$C,$B$4,'RAW 2025'!$P:$P,$A11) -> 0 | C11: =SUMIFS('RAW 2025'!$L:$L,'RAW 2025'!$C:$C,$C$4,'RAW 2025'!$P:$P,$A11) -> -428.77
A12: Dinner | B12: =SUMIFS('RAW 2025'!$L:$L,'RAW 2025'!$C:$C,$B$4,'RAW 2025'!$P:$P,$A12) -> 0 | C12: =SUMIFS('RAW 2025'!$L:$L,'RAW 2025'!$C:$C,$C$4,'RAW 2025'!$P:$P,$A12) -> -226.24
A13: Director's Salary | B13: =SUMIFS('RAW 2025'!$L:$L,'RAW 2025'!$C:$C,$B$4,'RAW 2025'!$P:$P,$A13) -> -1000 | C13: =SUMIFS('RAW 2025'!$L:$L,'RAW 2025'!$C:$C,$C$4,'RAW 2025'!$P:$P,$A13) -> -49250
A14: Directors salary | B14: =SUMIFS('RAW 2025'!$L:$L,'RAW 2025'!$C:$C,$B$4,'RAW 2025'!$P:$P,$A14) -> 0 | C14: =SUMIFS('RAW 2025'!$L:$L,'RAW 2025'!$C:$C,$C$4,'RAW 2025'!$P:$P,$A14) -> -11100
A15: Dividends | B15: =SUMIFS('RAW 2025'!$L:$L,'RAW 2025'!$C:$C,$B$4,'RAW 2025'!$P:$P,$A15) -> 0 | C15: =SUMIFS('RAW 2025'!$L:$L,'RAW 2025'!$C:$C,$C$4,'RAW 2025'!$P:$P,$A15) -> -40370
A16: Entertainment | B16: =SUMIFS('RAW 2025'!$L:$L,'RAW 2025'!$C:$C,$B$4,'RAW 2025'!$P:$P,$A16) -> 0 | C16: =SUMIFS('RAW 2025'!$L:$L,'RAW 2025'!$C:$C,$C$4,'RAW 2025'!$P:$P,$A16) -> -57.4
... A33: Univerisity fee? | B33: =SUMIFS('RAW 2025'!$L:$L,'RAW 2025'!$C:$C,$B$4,'RAW 2025'!$P:$P,$A33) -> 0 | C33: =SUMIFS('RAW 2025'!$L:$L,'RAW 2025'!$C:$C,$C$4,'RAW 2025'!$P:$P,$A33) -> -1400
A34: Grand Total | B34: =SUM(B5:B33) -> -1073 | C34: =SUM(C5:C33) -> 19070.7
